<?xml version="1.0" encoding="utf-8"?>
<!--
  Robot: xArm7 with gripper - HIGH FIDELITY VERSION
  
  Mesh locations (relative to assets/ folder):
    - Arm meshes: xarm/xarm_description/meshes/xarm7/visual/
    - Gripper meshes: xarm/xarm_gripper/meshes/
  
  COORDINATE SYSTEM:
    - Origin (0,0,0) = Robot base center, ON the table surface
    - +X = forward (toward objects)
    - +Y = left  
    - +Z = up
    
  Table surface is at Z=0 (robot mounted on table)
-->
<mujoco model="xarm7_plate_dishwasher_task">
  <!-- meshdir points to xarm/ folder, then we use relative paths -->
  <compiler angle="radian" autolimits="true" meshdir=""/>
  
  <option timestep="0.002" gravity="0 0 -9.81" integrator="implicitfast" cone="elliptic">
    <flag contact="enable"/>
  </option>
  
  <visual>
    <headlight diffuse="0.6 0.6 0.6" ambient="0.3 0.3 0.3" specular="0 0 0"/>
    <rgba haze="0.15 0.25 0.35 1"/>
    <global azimuth="120" elevation="-20"/>
    <quality shadowsize="4096"/>
    <map force="0.1" zfar="30"/>
  </visual>
  
  <asset>
    <texture name="texplane" type="2d" builtin="checker" rgb1="0.15 0.15 0.15" rgb2="0.25 0.25 0.25" width="512" height="512"/>
    <material name="matplane" texture="texplane" texrepeat="6 6" reflectance="0.1"/>
    <texture name="wood" type="2d" builtin="flat" rgb1="0.55 0.45 0.35" rgb2="0.5 0.4 0.3" width="256" height="256"/>
    <material name="wood" texture="wood" reflectance="0.05"/>
    
    <material name="white" rgba="1 1 1 1"/>
    <material name="gray" rgba="0.753 0.753 0.753 1"/>
    <material name="dark_gray" rgba="0.4 0.4 0.4 1"/>
    <material name="black" rgba="0.2 0.2 0.2 1"/>
    
    <!-- ARM MESHES (from xarm_description/meshes/xarm7/visual/) -->
    <mesh name="link_base" file="xarm_description/meshes/xarm7/visual/link_base.stl"/>
    <mesh name="link1" file="xarm_description/meshes/xarm7/visual/link1.stl"/>
    <mesh name="link2" file="xarm_description/meshes/xarm7/visual/link2.stl"/>
    <mesh name="link3" file="xarm_description/meshes/xarm7/visual/link3.stl"/>
    <mesh name="link4" file="xarm_description/meshes/xarm7/visual/link4.stl"/>
    <mesh name="link5" file="xarm_description/meshes/xarm7/visual/link5.stl"/>
    <mesh name="link6" file="xarm_description/meshes/xarm7/visual/link6.stl"/>
    <mesh name="link7" file="xarm_description/meshes/xarm7/visual/link7.stl"/>
    
    <!-- GRIPPER MESHES (from xarm_gripper/meshes/) -->
    <mesh name="gripper_base" file="xarm_gripper/meshes/base_link.stl"/>
    <mesh name="left_finger" file="xarm_gripper/meshes/left_finger.stl"/>
    <mesh name="right_finger" file="xarm_gripper/meshes/right_finger.stl"/>
    <mesh name="left_outer_knuckle" file="xarm_gripper/meshes/left_outer_knuckle.stl"/>
    <mesh name="right_outer_knuckle" file="xarm_gripper/meshes/right_outer_knuckle.stl"/>
    <mesh name="left_inner_knuckle" file="xarm_gripper/meshes/left_inner_knuckle.stl"/>
    <mesh name="right_inner_knuckle" file="xarm_gripper/meshes/right_inner_knuckle.stl"/>
  </asset>
  
  <default>
    <default class="xarm7">
      <geom type="mesh" material="white"/>
      <joint axis="0 0 1" armature="0.1" damping="5"/>
    </default>
    <default class="gripper">
      <geom rgba="0.7 0.7 0.7 1" friction="1.0 0.05 0.01"/>
    </default>
    <default class="finger">
      <geom rgba="0.5 0.5 0.5 1" friction="1.2 0.05 0.01" solimp="0.95 0.99 0.001" solref="0.004 1"/>
    </default>
    <default class="plate">
      <geom rgba="0.92 0.92 0.96 1" friction="0.8 0.02 0.01" solimp="0.95 0.99 0.001" solref="0.002 1"/>
    </default>
    <default class="rack">
      <geom rgba="0.3 0.3 0.3 1" friction="0.6 0.01 0.01"/>
    </default>
    <default class="table">
      <geom rgba="0.55 0.45 0.35 1"/>
    </default>
  </default>
  
  <worldbody>
    <geom name="floor" type="plane" size="2 2 0.1" pos="0 0 -0.75" material="matplane"/>
    <light pos="0.3 0 1.5" dir="0 0 -1" diffuse="0.8 0.8 0.8" specular="0.2 0.2 0.2"/>
    <light pos="-0.3 0.4 1.0" dir="0.2 -0.2 -0.9" diffuse="0.4 0.4 0.4"/>
    <light pos="0.5 -0.3 1.2" dir="-0.1 0.1 -0.9" diffuse="0.3 0.3 0.3"/>
    
    <!-- TABLE -->
    <body name="table" pos="0.2 0 0">
      <geom name="table_top" type="box" class="table" size="0.50 0.45 0.02" pos="0 0 -0.02" material="wood"/>
      <geom name="leg1" type="box" class="table" size="0.03 0.03 0.355" pos="-0.44 -0.39 -0.395"/>
      <geom name="leg2" type="box" class="table" size="0.03 0.03 0.355" pos="0.44 -0.39 -0.395"/>
      <geom name="leg3" type="box" class="table" size="0.03 0.03 0.355" pos="-0.44 0.39 -0.395"/>
      <geom name="leg4" type="box" class="table" size="0.03 0.03 0.355" pos="0.44 0.39 -0.395"/>
    </body>
    
    <!-- DISHWASHER RACK -->
    <body name="dishwasher_rack" pos="0.50 0.22 0.004">
      <geom name="rack_base" class="rack" type="box" size="0.10 0.08 0.004"/>
      <geom name="slot0" class="rack" type="box" size="0.002 0.065 0.05" pos="-0.065 0 0.054"/>
      <geom name="slot1" class="rack" type="box" size="0.002 0.065 0.05" pos="-0.0325 0 0.054"/>
      <geom name="slot2" class="rack" type="box" size="0.002 0.065 0.05" pos="0 0 0.054"/>
      <geom name="slot3" class="rack" type="box" size="0.002 0.065 0.05" pos="0.0325 0 0.054"/>
      <geom name="slot4" class="rack" type="box" size="0.002 0.065 0.05" pos="0.065 0 0.054"/>
      <geom name="wall_l" class="rack" type="box" size="0.003 0.08 0.055" pos="-0.097 0 0.059"/>
      <geom name="wall_r" class="rack" type="box" size="0.003 0.08 0.055" pos="0.097 0 0.059"/>
      <geom name="wall_f" class="rack" type="box" size="0.10 0.003 0.055" pos="0 -0.077 0.059"/>
      <geom name="wall_b" class="rack" type="box" size="0.10 0.003 0.055" pos="0 0.077 0.059"/>
      <site name="target_slot" pos="0.016 0 0.01" size="0.012 0.05 0.003" rgba="0 1 0 0.4" type="box"/>
    </body>
    
    <!-- PLATE -->
    <body name="plate" pos="0.40 -0.10 0.010">
      <freejoint name="plate_joint"/>
      <geom name="plate_base" class="plate" type="cylinder" size="0.085 0.010" mass="0.22"/>
      <geom name="plate_rim" type="cylinder" size="0.085 0.004" pos="0 0 0.010" rgba="0.88 0.88 0.92 1" mass="0.04"/>
      <site name="plate_center" pos="0 0 0.007" size="0.006" rgba="1 0 0 0.8"/>
      <site name="plate_edge1" pos="0.075 0 0.007" size="0.005" rgba="0 0 1 0.5"/>
      <site name="plate_edge2" pos="-0.075 0 0.007" size="0.005" rgba="0 0 1 0.5"/>
    </body>
    
    <!-- xArm7 ROBOT WITH HIGH-FIDELITY MESHES -->
    <body name="link_base" pos="0 0 0" childclass="xarm7">
      <geom name="base_visual" type="mesh" mesh="link_base" material="white" contype="0" conaffinity="0"/>
      <geom name="base_collision" type="cylinder" size="0.065 0.05" pos="0 0 0.05" rgba="1 1 1 0" group="3"/>
      
      <body name="link1" pos="0 0 0.267">
        <inertial pos="-0.0002 0.02905 -0.01233" mass="2.382" diaginertia="0.0056905 0.0049566 0.003316654"/>
        <joint name="joint1" range="-6.28 6.28" damping="10"/>
        <geom name="link1_visual" type="mesh" mesh="link1" material="white" contype="0" conaffinity="0"/>
        <geom name="link1_collision" type="cylinder" size="0.055 0.06" pos="0 0 -0.03" rgba="1 1 1 0" group="3"/>
        
        <body name="link2" pos="0 0 0" euler="-1.5708 0 0">
          <inertial pos="0.00022 -0.12856 0.01735" mass="1.869" diaginertia="0.0095989 0.00382472 0.007565669"/>
          <joint name="joint2" range="-2.059 2.0944" damping="10"/>
          <geom name="link2_visual" type="mesh" mesh="link2" material="white" contype="0" conaffinity="0"/>
          <geom name="link2_collision" type="capsule" size="0.048" fromto="0 0 0 0 -0.293 0" rgba="1 1 1 0" group="3"/>
          
          <body name="link3" pos="0 -0.293 0" euler="1.5708 0 0">
            <inertial pos="0.0466 -0.02463 -0.00768" mass="1.6383" diaginertia="0.00310955 0.00264483 0.0026624"/>
            <joint name="joint3" range="-6.28 6.28" damping="5"/>
            <geom name="link3_visual" type="mesh" mesh="link3" material="white" contype="0" conaffinity="0"/>
            <geom name="link3_collision" type="cylinder" size="0.045 0.035" pos="0.0525 0 0" euler="0 1.5708 0" rgba="1 1 1 0" group="3"/>
            
            <body name="link4" pos="0.0525 0 0" euler="1.5708 0 0">
              <inertial pos="0.07047 -0.11575 0.012" mass="1.7269" diaginertia="0.005889 0.00359703 0.00543244"/>
              <joint name="joint4" range="-0.19198 3.927" damping="5"/>
              <geom name="link4_visual" type="mesh" mesh="link4" material="white" contype="0" conaffinity="0"/>
              <geom name="link4_collision" type="capsule" size="0.042" fromto="0 0 0 0.0775 -0.3425 0" rgba="1 1 1 0" group="3"/>
              
              <body name="link5" pos="0.0775 -0.3425 0" euler="1.5708 0 0">
                <inertial pos="-0.00032 0.01604 -0.026" mass="1.3203" diaginertia="0.00534665 0.0049779 0.0013624"/>
                <joint name="joint5" range="-6.28 6.28" damping="5"/>
                <geom name="link5_visual" type="mesh" mesh="link5" material="white" contype="0" conaffinity="0"/>
                <geom name="link5_collision" type="cylinder" size="0.038 0.04" rgba="1 1 1 0" group="3"/>
                
                <body name="link6" pos="0 0 0" euler="1.5708 0 0">
                  <inertial pos="0.06469 0.03278 0.02141" mass="1.325" diaginertia="0.0014745 0.0019037 0.0023652"/>
                  <joint name="joint6" range="-1.69297 3.14159" damping="2"/>
                  <geom name="link6_visual" type="mesh" mesh="link6" material="gray" contype="0" conaffinity="0"/>
                  <geom name="link6_collision" type="capsule" size="0.032" fromto="0 0 0 0.076 0.097 0" rgba="1 1 1 0" group="3"/>
                  
                  <body name="link7" pos="0.076 0.097 0" euler="-1.5708 0 0">
                    <inertial pos="0 -0.00677 -0.01098" mass="0.17" diaginertia="9.3e-05 5.87e-05 0.000132"/>
                    <joint name="joint7" range="-6.28 6.28" damping="2"/>
                    <geom name="link7_visual" type="mesh" mesh="link7" material="gray" contype="0" conaffinity="0"/>
                    <geom name="link7_collision" type="cylinder" size="0.032 0.012" pos="0 0 -0.012" rgba="1 1 1 0" group="3"/>
                    <site name="ee_site" pos="0 0 0" size="0.008" rgba="1 0 0 0.5"/>
                    
                    <!-- GRIPPER WITH MESHES -->
                    <!-- The gripper attaches to link7's end. Positioning may need adjustment -->
                    <body name="xarm_gripper_base_link" pos="0 0 0">
                      <geom name="gripper_base_visual" type="mesh" mesh="gripper_base" material="dark_gray" contype="0" conaffinity="0"/>
                      
                      <!-- Drive joint for gripper open/close -->
                      <joint name="drive_joint" type="hinge" axis="1 0 0" pos="0 0.035 -0.059" range="0 0.85" damping="0.5"/>
                      
                      <!-- Left side -->
                      <body name="left_outer_knuckle" pos="0 0.035 -0.059">
                        <geom name="left_outer_knuckle_visual" type="mesh" mesh="left_outer_knuckle" class="gripper" contype="0" conaffinity="0"/>
                        <geom name="left_outer_knuckle_collision" type="box" size="0.008 0.012 0.018" pos="0 0.018 -0.015" rgba="1 1 1 0" group="3"/>
                        
                        <body name="left_finger" pos="0 0.035465 -0.042039">
                          <joint name="left_finger_joint" type="hinge" axis="1 0 0" range="0 0.85" damping="0.2"/>
                          <geom name="left_finger_visual" type="mesh" mesh="left_finger" class="finger" contype="0" conaffinity="0"/>
                          <geom name="left_finger_collision1" type="box" size="0.006 0.008 0.025" pos="0 0.008 -0.025" class="finger" group="3"/>
                          <geom name="left_finger_collision2" type="box" size="0.006 0.012 0.008" pos="0 0.012 -0.058" class="finger" group="3"/>
                        </body>
                      </body>
                      
                      <body name="left_inner_knuckle" pos="0 0.02 -0.074">
                        <joint name="left_inner_knuckle_joint" type="hinge" axis="1 0 0" range="0 0.85" damping="0.2"/>
                        <geom name="left_inner_knuckle_visual" type="mesh" mesh="left_inner_knuckle" class="gripper" contype="0" conaffinity="0"/>
                        <geom name="left_inner_knuckle_collision" type="box" size="0.006 0.006 0.015" pos="0 0.01 -0.015" rgba="1 1 1 0" group="3"/>
                      </body>
                      
                      <!-- Right side -->
                      <body name="right_outer_knuckle" pos="0 -0.035 -0.059">
                        <joint name="right_outer_knuckle_joint" type="hinge" axis="-1 0 0" range="0 0.85" damping="0.2"/>
                        <geom name="right_outer_knuckle_visual" type="mesh" mesh="right_outer_knuckle" class="gripper" contype="0" conaffinity="0"/>
                        <geom name="right_outer_knuckle_collision" type="box" size="0.008 0.012 0.018" pos="0 -0.018 -0.015" rgba="1 1 1 0" group="3"/>
                        
                        <body name="right_finger" pos="0 -0.035465 -0.042039">
                          <joint name="right_finger_joint" type="hinge" axis="1 0 0" range="0 0.85" damping="0.2"/>
                          <geom name="right_finger_visual" type="mesh" mesh="right_finger" class="finger" contype="0" conaffinity="0"/>
                          <geom name="right_finger_collision1" type="box" size="0.006 0.008 0.025" pos="0 -0.008 -0.025" class="finger" group="3"/>
                          <geom name="right_finger_collision2" type="box" size="0.006 0.012 0.008" pos="0 -0.012 -0.058" class="finger" group="3"/>
                        </body>
                      </body>
                      
                      <body name="right_inner_knuckle" pos="0 -0.02 -0.074">
                        <joint name="right_inner_knuckle_joint" type="hinge" axis="-1 0 0" range="0 0.85" damping="0.2"/>
                        <geom name="right_inner_knuckle_visual" type="mesh" mesh="right_inner_knuckle" class="gripper" contype="0" conaffinity="0"/>
                        <geom name="right_inner_knuckle_collision" type="box" size="0.006 0.006 0.015" pos="0 -0.01 -0.015" rgba="1 1 1 0" group="3"/>
                      </body>
                      
                      <!-- TCP (Tool Center Point) -->
                      <body name="link_tcp" pos="0 0 -0.172">
                        <site name="tcp_site" pos="0 0 0" size="0.006" rgba="0 1 0 1"/>
                      </body>
                    </body>
                  </body>
                </body>
              </body>
            </body>
          </body>
        </body>
      </body>
    </body>
  </worldbody>
  
  <actuator>
    <position name="act_j1" joint="joint1" kp="2000" kv="100"/>
    <position name="act_j2" joint="joint2" kp="2000" kv="100"/>
    <position name="act_j3" joint="joint3" kp="1500" kv="80"/>
    <position name="act_j4" joint="joint4" kp="1500" kv="80"/>
    <position name="act_j5" joint="joint5" kp="1000" kv="50"/>
    <position name="act_j6" joint="joint6" kp="500" kv="30"/>
    <position name="act_j7" joint="joint7" kp="500" kv="30"/>
    <position name="act_gripper" joint="drive_joint" kp="200" kv="10"/>
  </actuator>
  
  <equality>
    <joint joint1="drive_joint" joint2="left_finger_joint" polycoef="0 1 0 0 0"/>
    <joint joint1="drive_joint" joint2="left_inner_knuckle_joint" polycoef="0 1 0 0 0"/>
    <joint joint1="drive_joint" joint2="right_outer_knuckle_joint" polycoef="0 1 0 0 0"/>
    <joint joint1="drive_joint" joint2="right_finger_joint" polycoef="0 1 0 0 0"/>
    <joint joint1="drive_joint" joint2="right_inner_knuckle_joint" polycoef="0 1 0 0 0"/>
  </equality>
  
  <sensor>
    <framepos name="plate_pos" objtype="site" objname="plate_center"/>
    <framequat name="plate_quat" objtype="site" objname="plate_center"/>
    <framepos name="target_pos" objtype="site" objname="target_slot"/>
    <framepos name="tcp_pos" objtype="site" objname="tcp_site"/>
    <framequat name="tcp_quat" objtype="site" objname="tcp_site"/>
    <framepos name="ee_pos" objtype="site" objname="ee_site"/>
  </sensor>
  
  <keyframe>
    <key name="home" qpos="0 0 0 1.57 0 1.57 0  0 0 0 0 0 0  0.40 -0.10 0.010 1 0 0 0"/>
  </keyframe>
</mujoco>